<?xml version="1.0" ?>
<!-- =================================================================================== -->
<!-- |    This document was autogenerated by xacro from dual_gp4.urdf.xacro            | -->
<!-- |    EDITING THIS FILE BY HAND IS NOT RECOMMENDED                                 | -->
<!-- =================================================================================== -->
<robot name="dual_gp4">
  <link name="world"/>
  <!-- box shaped table as base for the 2 GP4 -->
  <link name="base">
    </link>
  <joint name="base_to_world" type="fixed">
    <parent link="world"/>
    <child link="base"/>
    <origin rpy="0.0 0.0 0.0" xyz="0.0 0.0 0.0"/>
  </joint>
  <joint name="left_arm_to_base" type="fixed">
    <parent link="base"/>
    <child link="left_arm_base"/>
    <origin rpy="0 0 0" xyz="0 0 0.9246"/>
    <dynamics damping="1.0"/>
  </joint>
  <!-- ROS-Industrial 'base' frame: base_link to gp4 World Coordinates transform -->
  <link name="left_arm_base"/>
  <joint name="left_arm_base_link-base" type="fixed">
    <origin rpy="0 0 0" xyz="0 0 0.0"/>
    <parent link="left_arm_base"/>
    <child link="left_arm_base_link"/>
  </joint>
  <!-- links: main serial chain -->
  <link name="left_arm_base_link">
    <inertial>
      <origin rpy="0 0 0" xyz="-0.073983 0.00022734 0.13031"/>
      <mass value="42.212"/>
      <inertia ixx="0.64296" ixy="0.0012624" ixz="-0.068804" iyy="1.2709" iyz="-0.0010754" izz="1.3497"/>
    </inertial>
    <visual>
      <geometry>
        <mesh filename="file:///root/catkin_ws/src/robot_digital_twin/meshes/gp4/base_link.stl"/>
      </geometry>
      <material name="">
        <color rgba="0.12941176470588237 0.14901960784313725 0.7490196078431373 1.0"/>
      </material>
    </visual>
    <collision>
      <geometry>
        <mesh filename="file:///root/catkin_ws/src/robot_digital_twin/meshes/gp4/base_link.stl"/>
      </geometry>
    </collision>
  </link>
  <link name="left_arm_link_1">
    <inertial>
      <origin rpy="0 0 0" xyz="0.058962 0.24363 -0.018725"/>
      <mass value="37.265"/>
      <inertia ixx="0.95018" ixy="-0.14402" ixz="-0.064915" iyy="1.0578" iyz="0.037699" izz="1.094"/>
    </inertial>
    <visual>
      <geometry>
        <mesh filename="file:///root/catkin_ws/src/robot_digital_twin/meshes/gp4/link_1.stl"/>
      </geometry>
      <material name="">
        <color rgba="0.12941176470588237 0.14901960784313725 0.7490196078431373 1.0"/>
      </material>
    </visual>
    <collision>
      <geometry>
        <mesh filename="file:///root/catkin_ws/src/robot_digital_twin/meshes/gp4/link_1.stl"/>
      </geometry>
    </collision>
  </link>
  <link name="left_arm_link_2">
    <inertial>
      <origin rpy="0 0 0" xyz="3.5083E-05 0.39008 0.15036"/>
      <mass value="22.632"/>
      <inertia ixx="1.7745" ixy="-0.0054743" ixz="0.00063015" iyy="0.15511" iyz="-0.09224" izz="1.826"/>
    </inertial>
    <visual>
      <geometry>
        <mesh filename="file:///root/catkin_ws/src/robot_digital_twin/meshes/gp4/link_2.stl"/>
      </geometry>
      <material name="">
        <color rgba="0.12941176470588237 0.14901960784313725 0.7490196078431373 1.0"/>
      </material>
    </visual>
    <collision>
      <geometry>
        <mesh filename="file:///root/catkin_ws/src/robot_digital_twin/meshes/gp4/link_2.stl"/>
      </geometry>
    </collision>
  </link>
  <link name="left_arm_link_3">
    <inertial>
      <origin rpy="0 0 0" xyz="0.086423 0.14427 -0.035793"/>
      <mass value="28.467"/>
      <inertia ixx="0.65771" ixy="-0.13627" ixz="-0.026219" iyy="0.52683" iyz="0.051956" izz="0.69722"/>
    </inertial>
    <visual>
      <geometry>
        <mesh filename="file:///root/catkin_ws/src/robot_digital_twin/meshes/gp4/link_3.stl"/>
      </geometry>
      <material name="">
        <color rgba="0.12941176470588237 0.14901960784313725 0.7490196078431373 1.0"/>
      </material>
    </visual>
    <collision>
      <geometry>
        <mesh filename="file:///root/catkin_ws/src/robot_digital_twin/meshes/gp4/link_3.stl"/>
      </geometry>
    </collision>
  </link>
  <link name="left_arm_link_4">
    <inertial>
      <origin rpy="0 0 0" xyz="0.37337 0.00033491 0.012656"/>
      <mass value="7.629"/>
      <inertia ixx="0.018151" ixy="-0.00033527" ixz="-0.031589" iyy="0.48072" iyz="3.3917E-05" izz="0.47647"/>
    </inertial>
    <visual>
      <geometry>
        <mesh filename="file:///root/catkin_ws/src/robot_digital_twin/meshes/gp4/link_4.stl"/>
      </geometry>
      <material name="">
        <color rgba="0.12941176470588237 0.14901960784313725 0.7490196078431373 1.0"/>
      </material>
    </visual>
    <collision>
      <geometry>
        <mesh filename="file:///root/catkin_ws/src/robot_digital_twin/meshes/gp4/link_4.stl"/>
      </geometry>
    </collision>
  </link>
  <link name="left_arm_link_5">
    <inertial>
      <origin rpy="0 0 0" xyz="0.062818 3.3289E-05 0.0048991"/>
      <mass value="2.5794"/>
      <inertia ixx="0.015161" ixy="-2.4835E-06" ixz="0.0016647" iyy="0.021382" iyz="-2.248E-06" izz="0.013473"/>
    </inertial>
    <visual>
      <geometry>
        <mesh filename="file:///root/catkin_ws/src/robot_digital_twin/meshes/gp4/link_5.stl"/>
      </geometry>
      <material name="">
        <color rgba="0.12941176470588237 0.14901960784313725 0.7490196078431373 1.0"/>
      </material>
    </visual>
    <collision>
      <geometry>
        <mesh filename="file:///root/catkin_ws/src/robot_digital_twin/meshes/gp4/link_5.stl"/>
      </geometry>
    </collision>
  </link>
  <link name="left_arm_link_6">
    <inertial>
      <origin rpy="0 0 0" xyz="0.00015982 -0.00063018 -0.008266"/>
      <mass value="0.10811"/>
      <inertia ixx="9.0129E-05" ixy="-1.0891E-08" ixz="9.1598E-09" iyy="9.2026E-05" iyz="-2.749E-07" izz="0.00017818"/>
    </inertial>
    <visual>
      <geometry>
        <mesh filename="file:///root/catkin_ws/src/robot_digital_twin/meshes/gp4/link_6.stl"/>
      </geometry>
      <material name="">
        <color rgba="0.8 0.8 0.8 1"/>
      </material>
    </visual>
    <collision>
      <geometry>
        <mesh filename="file:///root/catkin_ws/src/robot_digital_twin/meshes/gp4/link_6.stl"/>
      </geometry>
    </collision>
  </link>
  <link name="left_arm_fts">
    <collision>
      <origin rpy=" 0 0 0" xyz="0 0 0"/>
      <geometry>
        <cylinder length="0.0505" radius="0.035"/>
      </geometry>
    </collision>
    <visual>
      <origin rpy="0 0 0" xyz="0 0 0"/>
      <geometry>
        <cylinder length="0.0505" radius="0.035"/>
      </geometry>
      <material name="">
        <color rgba="0.8 0.8 0.8 1"/>
      </material>
    </visual>
    <inertial>
      <mass value="1e-5"/>
      <origin rpy="0 0 0" xyz="0 0 0"/>
      <inertia ixx="1e-6" ixy="0" ixz="0" iyy="1e-6" iyz="0" izz="1e-6"/>
    </inertial>
  </link>
  <link name="left_arm_link_tool">
    <inertial>
      <origin rpy="0 0 0" xyz="0 0 0"/>
      <mass value="0.10811"/>
      <inertia ixx="9.0129E-05" ixy="-1.0891E-08" ixz="9.1598E-09" iyy="9.2026E-05" iyz="-2.749E-07" izz="0.00017818"/>
    </inertial>
    <collision>
      <origin rpy="0 0 0" xyz="0 0 0"/>
      <geometry>
        <mesh filename="file:///root/catkin_ws/src/robot_digital_twin/meshes/eoat/tool_base_tilt.stl"/>
      </geometry>
    </collision>
    <visual>
      <origin rpy="0 0 0" xyz="0 0 0"/>
      <geometry>
        <mesh filename="file:///root/catkin_ws/src/robot_digital_twin/meshes/eoat/tool_base_tilt.stl"/>
      </geometry>
      <material name="">
        <color rgba="0.8 0.8 0.8 1"/>
      </material>
    </visual>
  </link>
  <link name="left_arm_link_precam">
    <inertial>
      <mass value="1e-5"/>
      <origin rpy="0 0 0" xyz="0 0 0"/>
      <inertia ixx="1e-6" ixy="0" ixz="0" iyy="1e-6" iyz="0" izz="1e-6"/>
    </inertial>
  </link>
  <link name="left_arm_link_camera">
    <inertial>
      <origin rpy="0 0 0" xyz="0 0 0"/>
      <mass value="0.10811"/>
      <inertia ixx="9.0129E-05" ixy="-1.0891E-08" ixz="9.1598E-09" iyy="9.2026E-05" iyz="-2.749E-07" izz="0.00017818"/>
    </inertial>
    <visual>
      <origin rpy="0 0 0" xyz="0 0 0"/>
      <geometry>
        <mesh filename="file:///root/catkin_ws/src/robot_digital_twin/meshes/eoat/tool_camera.stl"/>
      </geometry>
      <material name="">
        <color rgba="0.15 0.15 0.15 1.0"/>
      </material>
    </visual>
    <collision>
      <origin rpy="0 0 0" xyz="0 0 0"/>
      <geometry>
        <mesh filename="file:///root/catkin_ws/src/robot_digital_twin/meshes/eoat/tool_camera.stl"/>
      </geometry>
    </collision>
  </link>
  <link name="left_arm_link_camera_origin">
    <collision>
      <origin rpy="0 0 0" xyz="0 0 0"/>
      <geometry>
        <box size="0.0001 0.0001 0.0001"/>
      </geometry>
    </collision>
    <visual>
      <origin rpy="0 0 0" xyz="0 0 0"/>
      <geometry>
        <box size="0.0001 0.01 0.01"/>
      </geometry>
    </visual>
    <inertial>
      <mass value="1e-5"/>
      <origin rpy="0 0 0" xyz="0 0 0"/>
      <inertia ixx="1e-6" ixy="0" ixz="0" iyy="1e-6" iyz="0" izz="1e-6"/>
    </inertial>
  </link>
  <!-- joints: main serial chain -->
  <joint name="left_arm_joint_1" type="continuous">
    <parent link="left_arm_base_link"/>
    <child link="left_arm_link_1"/>
    <origin rpy="0 0 0" xyz="0 0 0.330"/>
    <axis xyz="0 0 1"/>
    <!-- <limit lower="${radians(-170)}" upper="${radians(170)}" effort="220.5" velocity="${radians(465)}"/> -->
    <!-- <limit effort="0" lower="${radians(-170)}" upper="${radians(170)}" velocity="${radians(370)}" /> -->
  </joint>
  <joint name="left_arm_joint_2" type="continuous">
    <parent link="left_arm_link_1"/>
    <child link="left_arm_link_2"/>
    <origin rpy="0 0 0" xyz="0 0 0"/>
    <axis xyz="0 1 0"/>
    <!-- <limit effort="100" lower="${radians(-100)}" upper="${radians(145)}" velocity="${radians(310)}" /> -->
  </joint>
  <joint name="left_arm_joint_3" type="continuous">
    <parent link="left_arm_link_2"/>
    <child link="left_arm_link_3"/>
    <origin rpy="0 0 0" xyz="0 0 0.260"/>
    <axis xyz="0 -1 0"/>
    <!-- <limit effort="0" lower="${radians(-70)}" upper="${radians(213)}" velocity="${radians(410)}" /> -->
  </joint>
  <joint name="left_arm_joint_4" type="continuous">
    <parent link="left_arm_link_3"/>
    <child link="left_arm_link_4"/>
    <origin rpy="0 0 0" xyz="0.290 0 0.015"/>
    <axis xyz="-1 0 0"/>
    <!-- <limit effort="0" lower="${radians(-190)}" upper="${radians(190)}" velocity="${radians(550)}" /> -->
  </joint>
  <joint name="left_arm_joint_5" type="continuous">
    <parent link="left_arm_link_4"/>
    <child link="left_arm_link_5"/>
    <origin rpy="0 0 0" xyz="0 0 0"/>
    <axis xyz="0 -1 0"/>
    <!-- <limit effort="0" lower="${radians(-125)}" upper="${radians(125)}" velocity="${radians(545)}" /> -->
  </joint>
  <joint name="left_arm_joint_6" type="continuous">
    <parent link="left_arm_link_5"/>
    <child link="left_arm_link_6"/>
    <origin rpy="0 0 0" xyz="0 0 0"/>
    <axis xyz="-1 0 0"/>
    <!-- <limit effort="0" lower="${radians(-360)}" upper="${radians(360)}" velocity="${radians(1000)}" /> -->
  </joint>
  <link name="left_arm_flange"/>
  <joint name="left_arm_joint_6_t-flange" type="fixed">
    <origin rpy="0 0 0" xyz="0.072 0 0"/>
    <parent link="left_arm_link_6"/>
    <child link="left_arm_flange"/>
  </joint>
  <joint name="left_arm_link_6_fts" type="fixed">
    <origin rpy="0 1.5707963267948966 0" xyz="0.02525 0 0"/>
    <parent link="left_arm_flange"/>
    <child link="left_arm_fts"/>
  </joint>
  <joint name="left_arm_fts_tool" type="revolute">
    <origin rpy="0 0 3.141592653589793" xyz="0 0 0.02525"/>
    <parent link="left_arm_fts"/>
    <child link="left_arm_link_tool"/>
    <axis xyz="0 0 1"/>
    <limit effort="0" lower="0" upper="0" velocity="0"/>
  </joint>
  <joint name="left_arm_tool_precam" type="fixed">
    <origin rpy="1.5707963267948966 -1.5707963267948966  0" xyz="0 -0.062194148 -0.005909903"/>
    <parent link="left_arm_link_tool"/>
    <child link="left_arm_link_precam"/>
  </joint>
  <joint name="left_arm_precam_camera" type="fixed">
    <origin rpy="0 0.7853981633974483 0" xyz="0 0 0"/>
    <parent link="left_arm_link_precam"/>
    <child link="left_arm_link_camera"/>
  </joint>
  <joint name="left_arm_camera_imgplane" type="fixed">
    <origin rpy="0 0 0" xyz="0.013 0.0 0.0305"/>
    <parent link="left_arm_link_camera"/>
    <child link="left_arm_link_camera_origin"/>
  </joint>
  <transmission name="trans_left_arm_joint_1">
    <type>transmission_interface/SimpleTransmission</type>
    <joint name="left_arm_joint_1">
      <hardwareInterface>hardware_interface/PositionJointInterface</hardwareInterface>
    </joint>
    <actuator name="left_arm_joint_1_motor">
      <hardwareInterface>hardware_interface/PositionJointInterface</hardwareInterface>
      <mechanicalReduction>1</mechanicalReduction>
    </actuator>
  </transmission>
  <transmission name="trans_left_arm_joint_2">
    <type>transmission_interface/SimpleTransmission</type>
    <joint name="left_arm_joint_2">
      <hardwareInterface>hardware_interface/PositionJointInterface</hardwareInterface>
    </joint>
    <actuator name="left_arm_joint_2_motor">
      <hardwareInterface>hardware_interface/PositionJointInterface</hardwareInterface>
      <mechanicalReduction>1</mechanicalReduction>
    </actuator>
  </transmission>
  <transmission name="trans_left_arm_joint_3">
    <type>transmission_interface/SimpleTransmission</type>
    <joint name="left_arm_joint_3">
      <hardwareInterface>hardware_interface/PositionJointInterface</hardwareInterface>
    </joint>
    <actuator name="left_arm_joint_3_motor">
      <hardwareInterface>hardware_interface/PositionJointInterface</hardwareInterface>
      <mechanicalReduction>1</mechanicalReduction>
    </actuator>
  </transmission>
  <transmission name="trans_left_arm_joint_4">
    <type>transmission_interface/SimpleTransmission</type>
    <joint name="left_arm_joint_4">
      <hardwareInterface>hardware_interface/PositionJointInterface</hardwareInterface>
    </joint>
    <actuator name="left_arm_joint_4_motor">
      <hardwareInterface>hardware_interface/PositionJointInterface</hardwareInterface>
      <mechanicalReduction>1</mechanicalReduction>
    </actuator>
  </transmission>
  <transmission name="trans_left_arm_joint_5">
    <type>transmission_interface/SimpleTransmission</type>
    <joint name="left_arm_joint_5">
      <hardwareInterface>hardware_interface/PositionJointInterface</hardwareInterface>
    </joint>
    <actuator name="left_arm_joint_5_motor">
      <hardwareInterface>hardware_interface/PositionJointInterface</hardwareInterface>
      <mechanicalReduction>1</mechanicalReduction>
    </actuator>
  </transmission>
  <transmission name="trans_left_arm_joint_6">
    <type>transmission_interface/SimpleTransmission</type>
    <joint name="left_arm_joint_6">
      <hardwareInterface>hardware_interface/PositionJointInterface</hardwareInterface>
    </joint>
    <actuator name="left_arm_joint_6_motor">
      <hardwareInterface>hardware_interface/PositionJointInterface</hardwareInterface>
      <mechanicalReduction>1</mechanicalReduction>
    </actuator>
  </transmission>
  <gazebo reference="fts_tool">
    <provideFeedback>true</provideFeedback>
  </gazebo>
  <gazebo>
    <provideFeedback>true</provideFeedback>
    <plugin filename="libgazebo_ros_ft_sensor.so" name="ft_sensor">
      <!-- <robotNamespace>/gp4_gazebo</robotNamespace> -->
      <alwaysOn> true </alwaysOn>
      <updateRate>125.0</updateRate>
      <topicName>left_arm_ft_sensor</topicName>
      <jointName>left_arm_fts_tool</jointName>
      <noise>
        <type>gaussian</type>
        <mean>0.0</mean>
        <stddev>0.001</stddev>
      </noise>
    </plugin>
  </gazebo>
  <gazebo reference="link_camera_origin">
    <sensor name="$depth_camera" type="depth">
      <update_rate>30</update_rate>
      <camera>
        <horizontal_fov>1.22173</horizontal_fov>
        <!-- 70deg -->
        <image>
          <width>1920</width>
          <height>1080</height>
          <format>R8G8B8</format>
        </image>
        <clip>
          <near>0.005</near>
          <far>2</far>
        </clip>
      </camera>
      <plugin filename="libgazebo_ros_openni_kinect.so" name="$depth_camera_controller">
        <baseline>0.2</baseline>
        <alwaysOn>true</alwaysOn>
        <updateRate>0</updateRate>
        <cameraName>left_arm_wrist_camera</cameraName>
        <frameName>left_arm_depth_camera_link</frameName>
        <pointCloudCutoff>0.005</pointCloudCutoff>
        <pointCloudCutoffMax>2.0</pointCloudCutoffMax>
        <distortionK1>0</distortionK1>
        <distortionK2>0</distortionK2>
        <distortionK3>0</distortionK3>
        <distortionT1>0</distortionT1>
        <distortionT2>0</distortionT2>
        <CxPrime>0</CxPrime>
        <Cx>0</Cx>
        <Cy>0</Cy>
        <focalLength>0</focalLength>
        <hackBaseline>0</hackBaseline>
      </plugin>
    </sensor>
  </gazebo>
  <gazebo reference="left_arm_base">
    <material>Gazebo/Blue</material>
    <visual>
      <transparency> 0 </transparency>
    </visual>
  </gazebo>
  <gazebo reference="left_arm_base_link">
    <material>Gazebo/Blue</material>
    <visual>
      <transparency> 0 </transparency>
    </visual>
  </gazebo>
  <gazebo reference="left_arm_link_1">
    <material>Gazebo/Blue</material>
    <visual>
      <transparency> 0 </transparency>
    </visual>
  </gazebo>
  <gazebo reference="left_arm_link_2">
    <material>Gazebo/Blue</material>
    <visual>
      <transparency> 0 </transparency>
    </visual>
  </gazebo>
  <gazebo reference="left_arm_link_3">
    <material>Gazebo/Blue</material>
    <visual>
      <transparency> 0 </transparency>
    </visual>
  </gazebo>
  <gazebo reference="left_arm_link_4">
    <material>Gazebo/Blue</material>
    <visual>
      <transparency> 0 </transparency>
    </visual>
  </gazebo>
  <gazebo reference="left_arm_link_5">
    <material>Gazebo/Blue</material>
    <visual>
      <transparency> 0 </transparency>
    </visual>
  </gazebo>
  <gazebo reference="left_arm_link_6">
    <material>Gazebo/Black</material>
    <visual>
      <transparency> 0 </transparency>
    </visual>
  </gazebo>
  <gazebo reference="left_arm_link_tool">
    <material>Gazebo/Black</material>
    <visual>
      <transparency> 0 </transparency>
    </visual>
  </gazebo>
  <gazebo reference="left_arm_fts">
    <material>Gazebo/Black</material>
    <visual>
      <transparency> 0 </transparency>
    </visual>
  </gazebo>
  <gazebo reference="left_arm_link_camera_origin">
    <material>Gazebo/Black</material>
    <visual>
      <transparency> 0 </transparency>
    </visual>
  </gazebo>
  <joint name="right_arm_to_base" type="fixed">
    <parent link="base"/>
    <child link="right_arm_base"/>
    <origin rpy="0 0 3.141592653589793" xyz="0.7951 0 0.9246"/>
    <dynamics damping="1.0"/>
  </joint>
  <!-- ROS-Industrial 'base' frame: base_link to gp4 World Coordinates transform -->
  <link name="right_arm_base"/>
  <joint name="right_arm_base_link-base" type="fixed">
    <origin rpy="0 0 0" xyz="0 0 0.0"/>
    <parent link="right_arm_base"/>
    <child link="right_arm_base_link"/>
  </joint>
  <!-- links: main serial chain -->
  <link name="right_arm_base_link">
    <inertial>
      <origin rpy="0 0 0" xyz="-0.073983 0.00022734 0.13031"/>
      <mass value="42.212"/>
      <inertia ixx="0.64296" ixy="0.0012624" ixz="-0.068804" iyy="1.2709" iyz="-0.0010754" izz="1.3497"/>
    </inertial>
    <visual>
      <geometry>
        <mesh filename="file:///root/catkin_ws/src/robot_digital_twin/meshes/gp4/base_link.stl"/>
      </geometry>
      <material name="">
        <color rgba="0.12941176470588237 0.14901960784313725 0.7490196078431373 1.0"/>
      </material>
    </visual>
    <collision>
      <geometry>
        <mesh filename="file:///root/catkin_ws/src/robot_digital_twin/meshes/gp4/base_link.stl"/>
      </geometry>
    </collision>
  </link>
  <link name="right_arm_link_1">
    <inertial>
      <origin rpy="0 0 0" xyz="0.058962 0.24363 -0.018725"/>
      <mass value="37.265"/>
      <inertia ixx="0.95018" ixy="-0.14402" ixz="-0.064915" iyy="1.0578" iyz="0.037699" izz="1.094"/>
    </inertial>
    <visual>
      <geometry>
        <mesh filename="file:///root/catkin_ws/src/robot_digital_twin/meshes/gp4/link_1.stl"/>
      </geometry>
      <material name="">
        <color rgba="0.12941176470588237 0.14901960784313725 0.7490196078431373 1.0"/>
      </material>
    </visual>
    <collision>
      <geometry>
        <mesh filename="file:///root/catkin_ws/src/robot_digital_twin/meshes/gp4/link_1.stl"/>
      </geometry>
    </collision>
  </link>
  <link name="right_arm_link_2">
    <inertial>
      <origin rpy="0 0 0" xyz="3.5083E-05 0.39008 0.15036"/>
      <mass value="22.632"/>
      <inertia ixx="1.7745" ixy="-0.0054743" ixz="0.00063015" iyy="0.15511" iyz="-0.09224" izz="1.826"/>
    </inertial>
    <visual>
      <geometry>
        <mesh filename="file:///root/catkin_ws/src/robot_digital_twin/meshes/gp4/link_2.stl"/>
      </geometry>
      <material name="">
        <color rgba="0.12941176470588237 0.14901960784313725 0.7490196078431373 1.0"/>
      </material>
    </visual>
    <collision>
      <geometry>
        <mesh filename="file:///root/catkin_ws/src/robot_digital_twin/meshes/gp4/link_2.stl"/>
      </geometry>
    </collision>
  </link>
  <link name="right_arm_link_3">
    <inertial>
      <origin rpy="0 0 0" xyz="0.086423 0.14427 -0.035793"/>
      <mass value="28.467"/>
      <inertia ixx="0.65771" ixy="-0.13627" ixz="-0.026219" iyy="0.52683" iyz="0.051956" izz="0.69722"/>
    </inertial>
    <visual>
      <geometry>
        <mesh filename="file:///root/catkin_ws/src/robot_digital_twin/meshes/gp4/link_3.stl"/>
      </geometry>
      <material name="">
        <color rgba="0.12941176470588237 0.14901960784313725 0.7490196078431373 1.0"/>
      </material>
    </visual>
    <collision>
      <geometry>
        <mesh filename="file:///root/catkin_ws/src/robot_digital_twin/meshes/gp4/link_3.stl"/>
      </geometry>
    </collision>
  </link>
  <link name="right_arm_link_4">
    <inertial>
      <origin rpy="0 0 0" xyz="0.37337 0.00033491 0.012656"/>
      <mass value="7.629"/>
      <inertia ixx="0.018151" ixy="-0.00033527" ixz="-0.031589" iyy="0.48072" iyz="3.3917E-05" izz="0.47647"/>
    </inertial>
    <visual>
      <geometry>
        <mesh filename="file:///root/catkin_ws/src/robot_digital_twin/meshes/gp4/link_4.stl"/>
      </geometry>
      <material name="">
        <color rgba="0.12941176470588237 0.14901960784313725 0.7490196078431373 1.0"/>
      </material>
    </visual>
    <collision>
      <geometry>
        <mesh filename="file:///root/catkin_ws/src/robot_digital_twin/meshes/gp4/link_4.stl"/>
      </geometry>
    </collision>
  </link>
  <link name="right_arm_link_5">
    <inertial>
      <origin rpy="0 0 0" xyz="0.062818 3.3289E-05 0.0048991"/>
      <mass value="2.5794"/>
      <inertia ixx="0.015161" ixy="-2.4835E-06" ixz="0.0016647" iyy="0.021382" iyz="-2.248E-06" izz="0.013473"/>
    </inertial>
    <visual>
      <geometry>
        <mesh filename="file:///root/catkin_ws/src/robot_digital_twin/meshes/gp4/link_5.stl"/>
      </geometry>
      <material name="">
        <color rgba="0.12941176470588237 0.14901960784313725 0.7490196078431373 1.0"/>
      </material>
    </visual>
    <collision>
      <geometry>
        <mesh filename="file:///root/catkin_ws/src/robot_digital_twin/meshes/gp4/link_5.stl"/>
      </geometry>
    </collision>
  </link>
  <link name="right_arm_link_6">
    <inertial>
      <origin rpy="0 0 0" xyz="0.00015982 -0.00063018 -0.008266"/>
      <mass value="0.10811"/>
      <inertia ixx="9.0129E-05" ixy="-1.0891E-08" ixz="9.1598E-09" iyy="9.2026E-05" iyz="-2.749E-07" izz="0.00017818"/>
    </inertial>
    <visual>
      <geometry>
        <mesh filename="file:///root/catkin_ws/src/robot_digital_twin/meshes/gp4/link_6.stl"/>
      </geometry>
      <material name="">
        <color rgba="0.8 0.8 0.8 1"/>
      </material>
    </visual>
    <collision>
      <geometry>
        <mesh filename="file:///root/catkin_ws/src/robot_digital_twin/meshes/gp4/link_6.stl"/>
      </geometry>
    </collision>
  </link>
  <link name="right_arm_fts">
    <collision>
      <origin rpy=" 0 0 0" xyz="0 0 0"/>
      <geometry>
        <cylinder length="0.0505" radius="0.035"/>
      </geometry>
    </collision>
    <visual>
      <origin rpy="0 0 0" xyz="0 0 0"/>
      <geometry>
        <cylinder length="0.0505" radius="0.035"/>
      </geometry>
      <material name="">
        <color rgba="0.8 0.8 0.8 1"/>
      </material>
    </visual>
    <inertial>
      <mass value="1e-5"/>
      <origin rpy="0 0 0" xyz="0 0 0"/>
      <inertia ixx="1e-6" ixy="0" ixz="0" iyy="1e-6" iyz="0" izz="1e-6"/>
    </inertial>
  </link>
  <link name="right_arm_link_tool">
    <inertial>
      <origin rpy="0 0 0" xyz="0 0 0"/>
      <mass value="0.10811"/>
      <inertia ixx="9.0129E-05" ixy="-1.0891E-08" ixz="9.1598E-09" iyy="9.2026E-05" iyz="-2.749E-07" izz="0.00017818"/>
    </inertial>
    <collision>
      <origin rpy="0 0 0" xyz="0 0 0"/>
      <geometry>
        <mesh filename="file:///root/catkin_ws/src/robot_digital_twin/meshes/eoat/tool_base_tilt.stl"/>
      </geometry>
    </collision>
    <visual>
      <origin rpy="0 0 0" xyz="0 0 0"/>
      <geometry>
        <mesh filename="file:///root/catkin_ws/src/robot_digital_twin/meshes/eoat/tool_base_tilt.stl"/>
      </geometry>
      <material name="">
        <color rgba="0.8 0.8 0.8 1"/>
      </material>
    </visual>
  </link>
  <link name="right_arm_link_precam">
    <inertial>
      <mass value="1e-5"/>
      <origin rpy="0 0 0" xyz="0 0 0"/>
      <inertia ixx="1e-6" ixy="0" ixz="0" iyy="1e-6" iyz="0" izz="1e-6"/>
    </inertial>
  </link>
  <link name="right_arm_link_camera">
    <inertial>
      <origin rpy="0 0 0" xyz="0 0 0"/>
      <mass value="0.10811"/>
      <inertia ixx="9.0129E-05" ixy="-1.0891E-08" ixz="9.1598E-09" iyy="9.2026E-05" iyz="-2.749E-07" izz="0.00017818"/>
    </inertial>
    <visual>
      <origin rpy="0 0 0" xyz="0 0 0"/>
      <geometry>
        <mesh filename="file:///root/catkin_ws/src/robot_digital_twin/meshes/eoat/tool_camera.stl"/>
      </geometry>
      <material name="">
        <color rgba="0.15 0.15 0.15 1.0"/>
      </material>
    </visual>
    <collision>
      <origin rpy="0 0 0" xyz="0 0 0"/>
      <geometry>
        <mesh filename="file:///root/catkin_ws/src/robot_digital_twin/meshes/eoat/tool_camera.stl"/>
      </geometry>
    </collision>
  </link>
  <link name="right_arm_link_camera_origin">
    <collision>
      <origin rpy="0 0 0" xyz="0 0 0"/>
      <geometry>
        <box size="0.0001 0.0001 0.0001"/>
      </geometry>
    </collision>
    <visual>
      <origin rpy="0 0 0" xyz="0 0 0"/>
      <geometry>
        <box size="0.0001 0.01 0.01"/>
      </geometry>
    </visual>
    <inertial>
      <mass value="1e-5"/>
      <origin rpy="0 0 0" xyz="0 0 0"/>
      <inertia ixx="1e-6" ixy="0" ixz="0" iyy="1e-6" iyz="0" izz="1e-6"/>
    </inertial>
  </link>
  <!-- joints: main serial chain -->
  <joint name="right_arm_joint_1" type="continuous">
    <parent link="right_arm_base_link"/>
    <child link="right_arm_link_1"/>
    <origin rpy="0 0 0" xyz="0 0 0.330"/>
    <axis xyz="0 0 1"/>
    <!-- <limit lower="${radians(-170)}" upper="${radians(170)}" effort="220.5" velocity="${radians(465)}"/> -->
    <!-- <limit effort="0" lower="${radians(-170)}" upper="${radians(170)}" velocity="${radians(370)}" /> -->
  </joint>
  <joint name="right_arm_joint_2" type="continuous">
    <parent link="right_arm_link_1"/>
    <child link="right_arm_link_2"/>
    <origin rpy="0 0 0" xyz="0 0 0"/>
    <axis xyz="0 1 0"/>
    <!-- <limit effort="100" lower="${radians(-100)}" upper="${radians(145)}" velocity="${radians(310)}" /> -->
  </joint>
  <joint name="right_arm_joint_3" type="continuous">
    <parent link="right_arm_link_2"/>
    <child link="right_arm_link_3"/>
    <origin rpy="0 0 0" xyz="0 0 0.260"/>
    <axis xyz="0 -1 0"/>
    <!-- <limit effort="0" lower="${radians(-70)}" upper="${radians(213)}" velocity="${radians(410)}" /> -->
  </joint>
  <joint name="right_arm_joint_4" type="continuous">
    <parent link="right_arm_link_3"/>
    <child link="right_arm_link_4"/>
    <origin rpy="0 0 0" xyz="0.290 0 0.015"/>
    <axis xyz="-1 0 0"/>
    <!-- <limit effort="0" lower="${radians(-190)}" upper="${radians(190)}" velocity="${radians(550)}" /> -->
  </joint>
  <joint name="right_arm_joint_5" type="continuous">
    <parent link="right_arm_link_4"/>
    <child link="right_arm_link_5"/>
    <origin rpy="0 0 0" xyz="0 0 0"/>
    <axis xyz="0 -1 0"/>
    <!-- <limit effort="0" lower="${radians(-125)}" upper="${radians(125)}" velocity="${radians(545)}" /> -->
  </joint>
  <joint name="right_arm_joint_6" type="continuous">
    <parent link="right_arm_link_5"/>
    <child link="right_arm_link_6"/>
    <origin rpy="0 0 0" xyz="0 0 0"/>
    <axis xyz="-1 0 0"/>
    <!-- <limit effort="0" lower="${radians(-360)}" upper="${radians(360)}" velocity="${radians(1000)}" /> -->
  </joint>
  <link name="right_arm_flange"/>
  <joint name="right_arm_joint_6_t-flange" type="fixed">
    <origin rpy="0 0 0" xyz="0.072 0 0"/>
    <parent link="right_arm_link_6"/>
    <child link="right_arm_flange"/>
  </joint>
  <joint name="right_arm_link_6_fts" type="fixed">
    <origin rpy="0 1.5707963267948966 0" xyz="0.02525 0 0"/>
    <parent link="right_arm_flange"/>
    <child link="right_arm_fts"/>
  </joint>
  <joint name="right_arm_fts_tool" type="revolute">
    <origin rpy="0 0 3.141592653589793" xyz="0 0 0.02525"/>
    <parent link="right_arm_fts"/>
    <child link="right_arm_link_tool"/>
    <axis xyz="0 0 1"/>
    <limit effort="0" lower="0" upper="0" velocity="0"/>
  </joint>
  <joint name="right_arm_tool_precam" type="fixed">
    <origin rpy="1.5707963267948966 -1.5707963267948966  0" xyz="0 -0.062194148 -0.005909903"/>
    <parent link="right_arm_link_tool"/>
    <child link="right_arm_link_precam"/>
  </joint>
  <joint name="right_arm_precam_camera" type="fixed">
    <origin rpy="0 0.7853981633974483 0" xyz="0 0 0"/>
    <parent link="right_arm_link_precam"/>
    <child link="right_arm_link_camera"/>
  </joint>
  <joint name="right_arm_camera_imgplane" type="fixed">
    <origin rpy="0 0 0" xyz="0.013 0.0 0.0305"/>
    <parent link="right_arm_link_camera"/>
    <child link="right_arm_link_camera_origin"/>
  </joint>
  <transmission name="trans_right_arm_joint_1">
    <type>transmission_interface/SimpleTransmission</type>
    <joint name="right_arm_joint_1">
      <hardwareInterface>hardware_interface/PositionJointInterface</hardwareInterface>
    </joint>
    <actuator name="right_arm_joint_1_motor">
      <hardwareInterface>hardware_interface/PositionJointInterface</hardwareInterface>
      <mechanicalReduction>1</mechanicalReduction>
    </actuator>
  </transmission>
  <transmission name="trans_right_arm_joint_2">
    <type>transmission_interface/SimpleTransmission</type>
    <joint name="right_arm_joint_2">
      <hardwareInterface>hardware_interface/PositionJointInterface</hardwareInterface>
    </joint>
    <actuator name="right_arm_joint_2_motor">
      <hardwareInterface>hardware_interface/PositionJointInterface</hardwareInterface>
      <mechanicalReduction>1</mechanicalReduction>
    </actuator>
  </transmission>
  <transmission name="trans_right_arm_joint_3">
    <type>transmission_interface/SimpleTransmission</type>
    <joint name="right_arm_joint_3">
      <hardwareInterface>hardware_interface/PositionJointInterface</hardwareInterface>
    </joint>
    <actuator name="right_arm_joint_3_motor">
      <hardwareInterface>hardware_interface/PositionJointInterface</hardwareInterface>
      <mechanicalReduction>1</mechanicalReduction>
    </actuator>
  </transmission>
  <transmission name="trans_right_arm_joint_4">
    <type>transmission_interface/SimpleTransmission</type>
    <joint name="right_arm_joint_4">
      <hardwareInterface>hardware_interface/PositionJointInterface</hardwareInterface>
    </joint>
    <actuator name="right_arm_joint_4_motor">
      <hardwareInterface>hardware_interface/PositionJointInterface</hardwareInterface>
      <mechanicalReduction>1</mechanicalReduction>
    </actuator>
  </transmission>
  <transmission name="trans_right_arm_joint_5">
    <type>transmission_interface/SimpleTransmission</type>
    <joint name="right_arm_joint_5">
      <hardwareInterface>hardware_interface/PositionJointInterface</hardwareInterface>
    </joint>
    <actuator name="right_arm_joint_5_motor">
      <hardwareInterface>hardware_interface/PositionJointInterface</hardwareInterface>
      <mechanicalReduction>1</mechanicalReduction>
    </actuator>
  </transmission>
  <transmission name="trans_right_arm_joint_6">
    <type>transmission_interface/SimpleTransmission</type>
    <joint name="right_arm_joint_6">
      <hardwareInterface>hardware_interface/PositionJointInterface</hardwareInterface>
    </joint>
    <actuator name="right_arm_joint_6_motor">
      <hardwareInterface>hardware_interface/PositionJointInterface</hardwareInterface>
      <mechanicalReduction>1</mechanicalReduction>
    </actuator>
  </transmission>
  <gazebo reference="fts_tool">
    <provideFeedback>true</provideFeedback>
  </gazebo>
  <gazebo>
    <provideFeedback>true</provideFeedback>
    <plugin filename="libgazebo_ros_ft_sensor.so" name="ft_sensor">
      <!-- <robotNamespace>/gp4_gazebo</robotNamespace> -->
      <alwaysOn> true </alwaysOn>
      <updateRate>125.0</updateRate>
      <topicName>right_arm_ft_sensor</topicName>
      <jointName>right_arm_fts_tool</jointName>
      <noise>
        <type>gaussian</type>
        <mean>0.0</mean>
        <stddev>0.001</stddev>
      </noise>
    </plugin>
  </gazebo>
  <gazebo reference="link_camera_origin">
    <sensor name="$depth_camera" type="depth">
      <update_rate>30</update_rate>
      <camera>
        <horizontal_fov>1.22173</horizontal_fov>
        <!-- 70deg -->
        <image>
          <width>1920</width>
          <height>1080</height>
          <format>R8G8B8</format>
        </image>
        <clip>
          <near>0.005</near>
          <far>2</far>
        </clip>
      </camera>
      <plugin filename="libgazebo_ros_openni_kinect.so" name="$depth_camera_controller">
        <baseline>0.2</baseline>
        <alwaysOn>true</alwaysOn>
        <updateRate>0</updateRate>
        <cameraName>right_arm_wrist_camera</cameraName>
        <frameName>right_arm_depth_camera_link</frameName>
        <pointCloudCutoff>0.005</pointCloudCutoff>
        <pointCloudCutoffMax>2.0</pointCloudCutoffMax>
        <distortionK1>0</distortionK1>
        <distortionK2>0</distortionK2>
        <distortionK3>0</distortionK3>
        <distortionT1>0</distortionT1>
        <distortionT2>0</distortionT2>
        <CxPrime>0</CxPrime>
        <Cx>0</Cx>
        <Cy>0</Cy>
        <focalLength>0</focalLength>
        <hackBaseline>0</hackBaseline>
      </plugin>
    </sensor>
  </gazebo>
  <gazebo reference="right_arm_base">
    <material>Gazebo/Blue</material>
    <visual>
      <transparency> 0 </transparency>
    </visual>
  </gazebo>
  <gazebo reference="right_arm_base_link">
    <material>Gazebo/Blue</material>
    <visual>
      <transparency> 0 </transparency>
    </visual>
  </gazebo>
  <gazebo reference="right_arm_link_1">
    <material>Gazebo/Blue</material>
    <visual>
      <transparency> 0 </transparency>
    </visual>
  </gazebo>
  <gazebo reference="right_arm_link_2">
    <material>Gazebo/Blue</material>
    <visual>
      <transparency> 0 </transparency>
    </visual>
  </gazebo>
  <gazebo reference="right_arm_link_3">
    <material>Gazebo/Blue</material>
    <visual>
      <transparency> 0 </transparency>
    </visual>
  </gazebo>
  <gazebo reference="right_arm_link_4">
    <material>Gazebo/Blue</material>
    <visual>
      <transparency> 0 </transparency>
    </visual>
  </gazebo>
  <gazebo reference="right_arm_link_5">
    <material>Gazebo/Blue</material>
    <visual>
      <transparency> 0 </transparency>
    </visual>
  </gazebo>
  <gazebo reference="right_arm_link_6">
    <material>Gazebo/Black</material>
    <visual>
      <transparency> 0 </transparency>
    </visual>
  </gazebo>
  <gazebo reference="right_arm_link_tool">
    <material>Gazebo/Black</material>
    <visual>
      <transparency> 0 </transparency>
    </visual>
  </gazebo>
  <gazebo reference="right_arm_fts">
    <material>Gazebo/Black</material>
    <visual>
      <transparency> 0 </transparency>
    </visual>
  </gazebo>
  <gazebo reference="right_arm_link_camera_origin">
    <material>Gazebo/Black</material>
    <visual>
      <transparency> 0 </transparency>
    </visual>
  </gazebo>
  <!-- load ros_control plugin -->
  <gazebo>
    <plugin filename="libgazebo_ros_control.so" name="gazebo_ros_control">
      <!-- <robotNamespace>/gp4_gazebo</robotNamespace> -->
      <robotSimType>gazebo_ros_control/DefaultRobotHWSim</robotSimType>
      <legacyModeNS>true</legacyModeNS>
    </plugin>
  </gazebo>
</robot>
